Workbook
Name Slicer_Diabetice_Status: #N/A
Name Slicer_Weight_Status: #N/A

Sheet Customer Names
A1: Customer ID | B1: Title | C1: First Name | D1: Last Name
A2: Id1 | B2: Ms | C2: Kelly | D2: Hawks
A3: Id2 | B3: Mr | C3: Matthew D | D3: Lehner
A4: Id3 | B4: Mr | C4: Phil | D4: Lu
A5: Id4 | B5: Ms | C5: Kelsey | D5: Osborne
A6: Id5 | B6: Ms | C6: Kristyn | D6: Kadala
A7: Id6 | B7: Mr | C7: Russell B | D7: Baker
A8: Id7 | B8: Mr | C8: Scott | D8: Macpherson
A9: Id8 | B9: Mr | C9: Stephen | D9: Hallman
A10: Id9 | B10: Mr | C10: Patrick R | D10: Moran
A11: Id10 | B11: Ms | C11: Brooke N | D11: Benner
A12: Id11 | B12: Ms | C12: Paola Andrea | D12: Fierro Vargas
... A2336: Id2335 | B2336: Mr | C2336: Aaron K | D2336: German

Sheet Medical Examinations
A1: Customer ID | B1: BMI | C1: Weight Status | D1: HBA1C | E1: Diabetice Status | F1: Heart Issues | G1: Any Transplants | H1: Cancer history | I1: Number Of Major Surgeries | J1: smoker
A2: Id1 | B2: 47.41 | C2: {=_xlfn.IFS(B2<18.5,"Underweight",B2<24.9,"Normal Weight",B2<30,"Overweight",B2>=30,"Obesity")} -> Obesity | D2: 7.47 | E2: {=_xlfn.IFS(D2<5.7,"Normal",D2<6.5,"Prediabetes",D2>=6.5,"Diabetes")} -> Diabetes | F2: No | G2: No | H2: No | I2: 0 | J2: Yes
A3: Id2 | B3: 30.36 | C3: {=_xlfn.IFS(B3<18.5,"Underweight",B3<24.9,"Normal Weight",B3<30,"Overweight",B3>=30,"Obesity")} -> Obesity | D3: 5.77 | E3: {=_xlfn.IFS(D3<5.7,"Normal",D3<6.5,"Prediabetes",D3>=6.5,"Diabetes")} -> Prediabetes | F3: No | G3: No | H3: No | I3: 0 | J3: Yes
A4: Id3 | B4: 34.485 | C4: {=_xlfn.IFS(B4<18.5,"Underweight",B4<24.9,"Normal Weight",B4<30,"Overweight",B4>=30,"Obesity")} -> Obesity | D4: 11.87 | E4: {=_xlfn.IFS(D4<5.7,"Normal",D4<6.5,"Prediabetes",D4>=6.5,"Diabetes")} -> Diabetes | F4: Yes | G4: No | H4: No | I4: 2 | J4: Yes
A5: Id4 | B5: 38.095 | C5: {=_xlfn.IFS(B5<18.5,"Underweight",B5<24.9,"Normal Weight",B5<30,"Overweight",B5>=30,"Obesity")} -> Obesity | D5: 6.05 | E5: {=_xlfn.IFS(D5<5.7,"Normal",D5<6.5,"Prediabetes",D5>=6.5,"Diabetes")} -> Prediabetes | F5: No | G5: No | H5: No | I5: 0 | J5: Yes
A6: Id5 | B6: 35.53 | C6: {=_xlfn.IFS(B6<18.5,"Underweight",B6<24.9,"Normal Weight",B6<30,"Overweight",B6>=30,"Obesity")} -> Obesity | D6: 5.45 | E6: {=_xlfn.IFS(D6<5.7,"Normal",D6<6.5,"Prediabetes",D6>=6.5,"Diabetes")} -> Normal | F6: No | G6: No | H6: No | I6: 0 | J6: Yes
A7: Id6 | B7: 32.8 | C7: {=_xlfn.IFS(B7<18.5,"Underweight",B7<24.9,"Normal Weight",B7<30,"Overweight",B7>=30,"Obesity")} -> Obesity | D7: 6.59 | E7: {=_xlfn.IFS(D7<5.7,"Normal",D7<6.5,"Prediabetes",D7>=6.5,"Diabetes")} -> Diabetes | F7: No | G7: No | H7: No | I7: 0 | J7: Yes
A8: Id7 | B8: 36.4 | C8: {=_xlfn.IFS(B8<18.5,"Underweight",B8<24.9,"Normal Weight",B8<30,"Overweight",B8>=30,"Obesity")} -> Obesity | D8: 6.07 | E8: {=_xlfn.IFS(D8<5.7,"Normal",D8<6.5,"Prediabetes",D8>=6.5,"Diabetes")} -> Prediabetes | F8: No | G8: No | H8: No | I8: 0 | J8: Yes
A9: Id8 | B9: 36.96 | C9: {=_xlfn.IFS(B9<18.5,"Underweight",B9<24.9,"Normal Weight",B9<30,"Overweight",B9>=30,"Obesity")} -> Obesity | D9: 7.93 | E9: {=_xlfn.IFS(D9<5.7,"Normal",D9<6.5,"Prediabetes",D9>=6.5,"Diabetes")} -> Diabetes | F9: No | G9: No | H9: No | I9: 3 | J9: Yes
A10: Id9 | B10: 41.14 | C10: {=_xlfn.IFS(B10<18.5,"Underweight",B10<24.9,"Normal Weight",B10<30,"Overweight",B10>=30,"Obesity")} -> Obesity | D10: 9.58 | E10: {=_xlfn.IFS(D10<5.7,"Normal",D10<6.5,"Prediabetes",D10>=6.5,"Diabetes")} -> Diabetes | F10: Yes | G10: No | H10: Yes | I10: 1 | J10: Yes
A11: Id10 | B11: 38.06 | C11: {=_xlfn.IFS(B11<18.5,"Underweight",B11<24.9,"Normal Weight",B11<30,"Overweight",B11>=30,"Obesity")} -> Obesity | D11: 10.79 | E11: {=_xlfn.IFS(D11<5.7,"Normal",D11<6.5,"Prediabetes",D11>=6.5,"Diabetes")} -> Diabetes | F11: No | G11: No | H11: No | I11: 0 | J11: Yes
A12: Id11 | B12: 37.7 | C12: {=_xlfn.IFS(B12<18.5,"Underweight",B12<24.9,"Normal Weight",B12<30,"Overweight",B12>=30,"Obesity")} -> Obesity | D12: 5.96 | E12: {=_xlfn.IFS(D12<5.7,"Normal",D12<6.5,"Prediabetes",D12>=6.5,"Diabetes")} -> Prediabetes | F12: Yes | G12: No | H12: No | I12: 2 | J12: Yes
A13: Id12 | B13: 42.13 | C13: {=_xlfn.IFS(B13<18.5,"Underweight",B13<24.9,"Normal Weight",B13<30,"Overweight",B13>=30,"Obesity")} -> Obesity | D13: 11.9 | E13: {=_xlfn.IFS(D13<5.7,"Normal",D13<6.5,"Prediabetes",D13>=6.5,"Diabetes")} -> Diabetes | F13: No | G13: No | H13: No | I13: 0 | J13: Yes
... A2336: Id2335 | B2336: 17.58 | C2336: {=_xlfn.IFS(B2336<18.5,"Underweight",B2336<24.9,"Normal Weight",B2336<30,"Overweight",B2336>=30,"Obesity")} -> Underweight | D2336: 4.51 | E2336: {=_xlfn.IFS(D2336<5.7,"Normal",D2336<6.5,"Prediabetes",D2336>=6.5,"Diabetes")} -> Normal | F2336: No | G2336: No | H2336: No | I2336: 1 | J2336: No
J2337: =COUNTBLANK(J2:J2336) -> 0

Sheet Hospitalisation Details
A1: Customer ID | B1: year | C1: year | D1: month | E1: month | F1: date | G1: Date of Birth | H1: Age | I1: children | J1: charges | K1: Hospital tier | L1: City tier | M1: State ID | N1: State ID | R1: ANSWERS
A2: Id2335 | B2: 1992 | C2: =ROUND(IF(ISBLANK(B2),AVERAGE($B$2:$B$2344),B2),0) -> 1992 | D2: Jul | E2: =IF(ISBLANK(D2),"Sep",D2) -> Jul | F2: 9 | G2: =DATEVALUE(F2&"-"&E2&"-"&C2) -> 33794 | H2: =DATEDIF(G2,"08-06-2023","y") -> 30 | I2: 0 | J2: 563.84 | K2: tier - 2 | L2: tier - 3 | M2: R1013 | N2: =IF(ISBLANK(M2),"Unknown",M2) -> R1013 | R2: PHASE - 1
A3: Id2334 | B3: 1992 | C3: =ROUND(IF(ISBLANK(B3),AVERAGE($B$2:$B$2344),B3),0) -> 1992 | D3: Nov | E3: =IF(ISBLANK(D3),"Sep",D3) -> Nov | F3: 30 | G3: =DATEVALUE(F3&"-"&E3&"-"&C3) -> 33938 | H3: =DATEDIF(G3,"08-06-2023","y") -> 30 | I3: 0 | J3: 570.62 | K3: tier - 2 | L3: tier - 1 | M3: R1013 | N3: =IF(ISBLANK(M3),"Unknown",M3) -> R1013 | Q3: 1 | R3: In this question, first we do the function of "COUNTIF", in this function we chose the condition like the count of "?" filled columns.
A4: Id2333 | B4: 1993 | C4: =ROUND(IF(ISBLANK(B4),AVERAGE($B$2:$B$2344),B4),0) -> 1993 | D4: Jun | E4: =IF(ISBLANK(D4),"Sep",D4) -> Jun | F4: 30 | G4: =DATEVALUE(F4&"-"&E4&"-"&C4) -> 34150 | H4: =DATEDIF(G4,"08-06-2023","y") -> 29 | I4: 0 | J4: 600 | K4: tier - 2 | L4: tier - 1 | M4: R1013 | N4: =IF(ISBLANK(M4),"Unknown",M4) -> R1013 | Q4: 2 | R4: we can chose the functions like "IF,ISBLANK,AVEAGE". In the case of numerical values chose the combained form of IF,ISBLANK,AVERAGE. In the case of defalt we chose certain name, in this question replace with "Sep" in the month column and average in the blanked year column.
A5: Id2332 | B5: 1992 | C5: =ROUND(IF(ISBLANK(B5),AVERAGE($B$2:$B$2344),B5),0) -> 1992 | D5: Sep | E5: =IF(ISBLANK(D5),"Sep",D5) -> Sep | F5: 13 | G5: =DATEVALUE(F5&"-"&E5&"-"&C5) -> 33860 | H5: =DATEDIF(G5,"08-06-2023","y") -> 30 | I5: 0 | J5: 604.54 | K5: tier - 3 | L5: tier - 3 | M5: R1013 | N5: =IF(ISBLANK(M5),"Unknown",M5) -> R1013 | Q5: 3 | R5: In this case,I chose the COUNTIF, by the condion of "tier"and "Yes or No", because, these are defalt data so ,in this case we cant use MODE. Then I took most repeted data to fill. So in these are most repeted data "tier -2" In hospital tier,"tier - 2" in city tier and "No" is the smoker repeted.
A6: Id2331 | B6: 1998 | C6: =ROUND(IF(ISBLANK(B6),AVERAGE($B$2:$B$2344),B6),0) -> 1998 | D6: Jul | E6: =IF(ISBLANK(D6),"Sep",D6) -> Jul | F6: 27 | G6: =DATEVALUE(F6&"-"&E6&"-"&C6) -> 36003 | H6: =DATEDIF(G6,"08-06-2023","y") -> 24 | I6: 0 | J6: 637.26 | K6: tier - 3 | L6: tier - 3 | M6: R1013 | N6: =IF(ISBLANK(M6),"Unknown",M6) -> R1013 | Q6: 4 | R6: Here we can use IFISBLANK functin
A7: Id2330 | B7: 2001 | C7: =ROUND(IF(ISBLANK(B7),AVERAGE($B$2:$B$2344),B7),0) -> 2001 | D7: Nov | E7: =IF(ISBLANK(D7),"Sep",D7) -> Nov | F7: 20 | G7: =DATEVALUE(F7&"-"&E7&"-"&C7) -> 37215 | H7: =DATEDIF(G7,"08-06-2023","y") -> 21 | I7: 0 | J7: 646.14 | K7: tier - 3 | L7: tier - 3 | M7: R1012 | N7: =IF(ISBLANK(M7),"Unknown",M7) -> R1012 | R7: PHASE - 2
A8: Id2329 | B8: 1993 | C8: =ROUND(IF(ISBLANK(B8),AVERAGE($B$2:$B$2344),B8),0) -> 1993 | D8: Jun | E8: =IF(ISBLANK(D8),"Sep",D8) -> Jun | F8: 1 | G8: =DATEVALUE(F8&"-"&E8&"-"&C8) -> 34121 | H8: =DATEDIF(G8,"08-06-2023","y") -> 30 | I8: 0 | J8: 650 | K8: tier - 3 | L8: tier - 3 | M8: R1013 | N8: =IF(ISBLANK(M8),"Unknown",M8) -> R1013 | Q8: 1 | R8: used text to column
A9: Id2328 | B9: 1995 | C9: =ROUND(IF(ISBLANK(B9),AVERAGE($B$2:$B$2344),B9),0) -> 1995 | D9: Jul | E9: =IF(ISBLANK(D9),"Sep",D9) -> Jul | F9: 4 | G9: =DATEVALUE(F9&"-"&E9&"-"&C9) -> 34884 | H9: =DATEDIF(G9,"08-06-2023","y") -> 27 | I9: 0 | J9: 650 | K9: tier - 3 | L9: tier - 3 | M9: R1013 | N9: =IF(ISBLANK(M9),"Unknown",M9) -> R1013 | Q9: 2 | R9: to replace with "0" on the defalt values
A10: Id2327 | B10: 2002 | C10: =ROUND(IF(ISBLANK(B10),AVERAGE($B$2:$B$2344),B10),0) -> 2002 | D10: Nov | E10: =IF(ISBLANK(D10),"Sep",D10) -> Nov | F10: 29 | G10: =DATEVALUE(F10&"-"&E10&"-"&C10) -> 37589 | H10: =DATEDIF(G10,"08-06-2023","y") -> 20 | I10: 0 | J10: 668 | K10: tier - 3 | L10: tier - 2 | M10: R1012 | N10: =IF(ISBLANK(M10),"Unknown",M10) -> R1012 | Q10: 3 | R10: in here inconsistancy is , the words not proper, so we use find and replce to change that
A11: Id2326 | B11: 1997 | C11: =ROUND(IF(ISBLANK(B11),AVERAGE($B$2:$B$2344),B11),0) -> 1997 | D11: Nov | E11: =IF(ISBLANK(D11),"Sep",D11) -> Nov | F11: 9 | G11: =DATEVALUE(F11&"-"&E11&"-"&C11) -> 35743 | H11: =DATEDIF(G11,"08-06-2023","y") -> 25 | I11: 0 | J11: 670 | K11: tier - 3 | L11: tier - 3 | M11: R1013 | N11: =IF(ISBLANK(M11),"Unknown",M11) -> R1013 | Q11: 4 | R11: Use the IFS fuction
A12: Id2325 | B12: 2001 | C12: =ROUND(IF(ISBLANK(B12),AVERAGE($B$2:$B$2344),B12),0) -> 2001 | D12: Sep | E12: =IF(ISBLANK(D12),"Sep",D12) -> Sep | F12: 12 | G12: =DATEVALUE(F12&"-"&E12&"-"&C12) -> 37146 | H12: =DATEDIF(G12,"08-06-2023","y") -> 21 | I12: 0 | J12: 687.54 | K12: tier - 3 | L12: tier - 2 | M12: R1013 | N12: =IF(ISBLANK(M12),"Unknown",M12) -> R1013 | Q12: 5 | R12: Use the IFS fuction
A13: Id2324 | B13: 1999 | C13: =ROUND(IF(ISBLANK(B13),AVERAGE($B$2:$B$2344),B13),0) -> 1999 | D13: Dec | E13: =IF(ISBLANK(D13),"Sep",D13) -> Dec | F13: 26 | G13: =DATEVALUE(F13&"-"&E13&"-"&C13) -> 36520 | H13: =DATEDIF(G13,"08-06-2023","y") -> 23 | I13: 0 | J13: 700 | K13: tire - 2 | L13: tier - 3 | M13: R1013 | N13: =IF(ISBLANK(M13),"Unknown",M13) -> R1013 | Q13: 6 | R13: to merger that column and use DATEVALUE
A14: Id2323 | B14: 1999 | C14: =ROUND(IF(ISBLANK(B14),AVERAGE($B$2:$B$2344),B14),0) -> 1999 | D14: Dec | E14: =IF(ISBLANK(D14),"Sep",D14) -> Dec | F14: 14 | G14: =DATEVALUE(F14&"-"&E14&"-"&C14) -> 36508 | H14: =DATEDIF(G14,"08-06-2023","y") -> 23 | I14: 0 | J14: 722.99 | K14: tier - 3 | L14: tier - 1 | M14: R1013 | N14: =IF(ISBLANK(M14),"Unknown",M14) -> R1013 | Q14: 7 | R14: Here we can use DATEDIF functin, To find exact age.
A15: Id2322 | B15: 2002 | C15: =ROUND(IF(ISBLANK(B15),AVERAGE($B$2:$B$2344),B15),0) -> 2002 | E15: =IF(ISBLANK(D15),"Sep",D15) -> Sep | F15: 19 | G15: =DATEVALUE(F15&"-"&E15&"-"&C15) -> 37518 | H15: =DATEDIF(G15,"08-06-2023","y") -> 20 | I15: 0 | J15: 750 | K15: tier - 3 | L15: tier - 1 | M15: R1012 | N15: =IF(ISBLANK(M15),"Unknown",M15) -> R1012
A16: Id2321 | B16: 1993 | C16: =ROUND(IF(ISBLANK(B16),AVERAGE($B$2:$B$2344),B16),0) -> 1993 | D16: Aug | E16: =IF(ISBLANK(D16),"Sep",D16) -> Aug | F16: 9 | G16: =DATEVALUE(F16&"-"&E16&"-"&C16) -> 34190 | H16: =DATEDIF(G16,"08-06-2023","y") -> 29 | I16: 0 | J16: 760 | K16: tier - 3 | L16: tier - 1 | M16: R1013 | N16: =IF(ISBLANK(M16),"Unknown",M16) -> R1013
A17: Id2320 | B17: 1996 | C17: =ROUND(IF(ISBLANK(B17),AVERAGE($B$2:$B$2344),B17),0) -> 1996 | D17: Oct | E17: =IF(ISBLANK(D17),"Sep",D17) -> Oct | F17: 22 | G17: =DATEVALUE(F17&"-"&E17&"-"&C17) -> 35360 | H17: =DATEDIF(G17,"08-06-2023","y") -> 26 | I17: 0 | J17: 760 | K17: tier - 3 | L17: tier - 3 | M17: R1013 | N17: =IF(ISBLANK(M17),"Unknown",M17) -> R1013
A18: Id2319 | B18: 1993 | C18: =ROUND(IF(ISBLANK(B18),AVERAGE($B$2:$B$2344),B18),0) -> 1993 | D18: Jun | E18: =IF(ISBLANK(D18),"Sep",D18) -> Jun | F18: 28 | G18: =DATEVALUE(F18&"-"&E18&"-"&C18) -> 34148 | H18: =DATEDIF(G18,"08-06-2023","y") -> 29 | I18: 0 | J18: 770 | K18: tier - 3 | L18: tier - 3 | M18: R1013 | N18: =IF(ISBLANK(M18),"Unknown",M18) -> R1013
A19: Id2318 | B19: 1996 | C19: =ROUND(IF(ISBLANK(B19),AVERAGE($B$2:$B$2344),B19),0) -> 1996 | E19: =IF(ISBLANK(D19),"Sep",D19) -> Sep | F19: 18 | G19: =DATEVALUE(F19&"-"&E19&"-"&C19) -> 35326 | H19: =DATEDIF(G19,"08-06-2023","y") -> 26 | I19: 0 | J19: 770.38 | K19: tier - 3 | L19: tier - 2 | M19: R1012 | N19: =IF(ISBLANK(M19),"Unknown",M19) -> R1012
A20: Id2317 | B20: 1995 | C20: =ROUND(IF(ISBLANK(B20),AVERAGE($B$2:$B$2344),B20),0) -> 1995 | D20: Dec | E20: =IF(ISBLANK(D20),"Sep",D20) -> Dec | F20: 7 | G20: =DATEVALUE(F20&"-"&E20&"-"&C20) -> 35040 | H20: =DATEDIF(G20,"08-06-2023","y") -> 27 | I20: 0 | J20: 773.54 | K20: tier - 3 | L20: tier - 2 | M20: R1013 | N20: =IF(ISBLANK(M20),"Unknown",M20) -> R1013
A21: Id2316 | B21: 2004 | C21: =ROUND(IF(ISBLANK(B21),AVERAGE($B$2:$B$2344),B21),0) -> 2004 | D21: Oct | E21: =IF(ISBLANK(D21),"Sep",D21) -> Oct | F21: 7 | G21: =DATEVALUE(F21&"-"&E21&"-"&C21) -> 38267 | H21: =DATEDIF(G21,"08-06-2023","y") -> 18 | I21: 0 | J21: 830.52 | K21: tier - 3 | L21: tier - 2 | M21: R1011 | N21: =IF(ISBLANK(M21),"Unknown",M21) -> R1011
A22: Id2315 | B22: 2000 | C22: =ROUND(IF(ISBLANK(B22),AVERAGE($B$2:$B$2344),B22),0) -> 2000 | D22: Nov | E22: =IF(ISBLANK(D22),"Sep",D22) -> Nov | F22: 18 | G22: =DATEVALUE(F22&"-"&E22&"-"&C22) -> 36848 | H22: =DATEDIF(G22,"08-06-2023","y") -> 22 | I22: 0 | J22: 865.41 | K22: tier - 3 | L22: tier - 1 | M22: R1013 | N22: =IF(ISBLANK(M22),"Unknown",M22) -> R1013
A23: Id2314 | B23: 1993 | C23: =ROUND(IF(ISBLANK(B23),AVERAGE($B$2:$B$2344),B23),0) -> 1993 | D23: Nov | E23: =IF(ISBLANK(D23),"Sep",D23) -> Nov | F23: 27 | G23: =DATEVALUE(F23&"-"&E23&"-"&C23) -> 34300 | H23: =DATEDIF(G23,"08-06-2023","y") -> 29 | I23: 0 | J23: 896.21 | K23: tier - 3 | L23: tier - 1 | M23: R1013 | N23: =IF(ISBLANK(M23),"Unknown",M23) -> R1013
A24: Id2313 | B24: 1994 | C24: =ROUND(IF(ISBLANK(B24),AVERAGE($B$2:$B$2344),B24),0) -> 1994 | D24: Oct | E24: =IF(ISBLANK(D24),"Sep",D24) -> Oct | F24: 30 | G24: =DATEVALUE(F24&"-"&E24&"-"&C24) -> 34637 | H24: =DATEDIF(G24,"08-06-2023","y") -> 28 | I24: 0 | J24: 915.07 | K24: tier - 3 | L24: tier - 1 | M24: R1013 | N24: =IF(ISBLANK(M24),"Unknown",M24) -> R1013
A25: Id2312 | B25: 1995 | C25: =ROUND(IF(ISBLANK(B25),AVERAGE($B$2:$B$2344),B25),0) -> 1995 | D25: Oct | E25: =IF(ISBLANK(D25),"Sep",D25) -> Oct | F25: 28 | G25: =DATEVALUE(F25&"-"&E25&"-"&C25) -> 35000 | H25: =DATEDIF(G25,"08-06-2023","y") -> 27 | I25: 0 | J25: 928.59 | K25: tier - 3 | L25: tier - 1 | M25: R1013 | N25: =IF(ISBLANK(M25),"Unknown",M25) -> R1013
A26: Id2311 | B26: 2001 | C26: =ROUND(IF(ISBLANK(B26),AVERAGE($B$2:$B$2344),B26),0) -> 2001 | D26: Aug | E26: =IF(ISBLANK(D26),"Sep",D26) -> Aug | F26: 19 | G26: =DATEVALUE(F26&"-"&E26&"-"&C26) -> 37122 | H26: =DATEDIF(G26,"08-06-2023","y") -> 21 | I26: 0 | J26: 964.71 | K26: tier - 3 | L26: tier - 2 | M26: R1013 | N26: =IF(ISBLANK(M26),"Unknown",M26) -> R1013
A27: Id2310 | B27: 1994 | C27: =ROUND(IF(ISBLANK(B27),AVERAGE($B$2:$B$2344),B27),0) -> 1994 | D27: Nov | E27: =IF(ISBLANK(D27),"Sep",D27) -> Nov | F27: 22 | G27: =DATEVALUE(F27&"-"&E27&"-"&C27) -> 34660 | H27: =DATEDIF(G27,"08-06-2023","y") -> 28 | I27: 0 | J27: 1006.65 | K27: tier - 3 | L27: tier - 2 | M27: R1013 | N27: =IF(ISBLANK(M27),"Unknown",M27) -> R1013
A28: Id2309 | B28: 2000 | C28: =ROUND(IF(ISBLANK(B28),AVERAGE($B$2:$B$2344),B28),0) -> 2000 | D28: Oct | E28: =IF(ISBLANK(D28),"Sep",D28) -> Oct | F28: 9 | G28: =DATEVALUE(F28&"-"&E28&"-"&C28) -> 36808 | H28: =DATEDIF(G28,"08-06-2023","y") -> 22 | I28: 0 | J28: 1012 | K28: tier - 3 | L28: tier - 2 | M28: R1013 | N28: =IF(ISBLANK(M28),"Unknown",M28) -> R1013
A29: Id2308 | B29: 1999 | C29: =ROUND(IF(ISBLANK(B29),AVERAGE($B$2:$B$2344),B29),0) -> 1999 | D29: Aug | E29: =IF(ISBLANK(D29),"Sep",D29) -> Aug | F29: 5 | G29: =DATEVALUE(F29&"-"&E29&"-"&C29) -> 36377 | H29: =DATEDIF(G29,"08-06-2023","y") -> 23 | I29: 0 | J29: 1019 | K29: tier - 3 | L29: tier - 2 | M29: R1013 | N29: =IF(ISBLANK(M29),"Unknown",M29) -> R1013
A30: Id2307 | B30: 1995 | C30: =ROUND(IF(ISBLANK(B30),AVERAGE($B$2:$B$2344),B30),0) -> 1995 | D30: Oct | E30: =IF(ISBLANK(D30),"Sep",D30) -> Oct | F30: 5 | G30: =DATEVALUE(F30&"-"&E30&"-"&C30) -> 34977 | H30: =DATEDIF(G30,"08-06-2023","y") -> 27 | I30: 0 | J30: 1033.74 | K30: tier - 3 | L30: tier - 1 | M30: R1013 | N30: =IF(ISBLANK(M30),"Unknown",M30) -> R1013
A31: Id2306 | B31: 1994 | C31: =ROUND(IF(ISBLANK(B31),AVERAGE($B$2:$B$2344),B31),0) -> 1994 | D31: Nov | E31: =IF(ISBLANK(D31),"Sep",D31) -> Nov | F31: 17 | G31: =DATEVALUE(F31&"-"&E31&"-"&C31) -> 34655 | H31: =DATEDIF(G31,"08-06-2023","y") -> 28 | I31: 0 | J31: 1044 | K31: tier - 3 | L31: tier - 2 | M31: R1013 | N31: =IF(ISBLANK(M31),"Unknown",M31) -> R1013
... A46: Id2291 | B46: 2002 | C46: =ROUND(IF(ISBLANK(B46),AVERAGE($B$2:$B$2344),B46),0) -> 2002 | D46: Aug | E46: =IF(ISBLANK(D46),"Sep",D46) -> Aug | F46: 11 | G46: =DATEVALUE(F46&"-"&E46&"-"&C46) -> 37479 | H46: =DATEDIF(G46,"08-06-2023","y") -> 20 | I46: 0 | J46: 1137 | K46: tier - 3 | L46: tier - 1 | M46: R1013 | N46: =IF(ISBLANK(M46),"Unknown",M46) -> R1013
B47: 2004 | C47: =ROUND(IF(ISBLANK(B47),AVERAGE($B$2:$B$2344),B47),0) -> 2004 | D47: Nov | E47: =IF(ISBLANK(D47),"Sep",D47) -> Nov | F47: 6 | G47: =DATEVALUE(F47&"-"&E47&"-"&C47) -> 38297 | H47: =DATEDIF(G47,"08-06-2023","y") -> 18 | I47: 0 | J47: 1137.01 | K47: tier - 3 | L47: tier - 1 | M47: R1013 | N47: =IF(ISBLANK(M47),"Unknown",M47) -> R1013
A48: Id2290 | B48: 2004 | C48: =ROUND(IF(ISBLANK(B48),AVERAGE($B$2:$B$2344),B48),0) -> 2004 | D48: Oct | E48: =IF(ISBLANK(D48),"Sep",D48) -> Oct | F48: 15 | G48: =DATEVALUE(F48&"-"&E48&"-"&C48) -> 38275 | H48: =DATEDIF(G48,"08-06-2023","y") -> 18 | I48: 0 | J48: 1137.01 | K48: tier - 3 | L48: tier - 1 | M48: R1013 | N48: =IF(ISBLANK(M48),"Unknown",M48) -> R1013
A49: Id2289 | B49: 2004 | C49: =ROUND(IF(ISBLANK(B49),AVERAGE($B$2:$B$2344),B49),0) -> 2004 | D49: Nov | E49: =IF(ISBLANK(D49),"Sep",D49) -> Nov | F49: 27 | G49: =DATEVALUE(F49&"-"&E49&"-"&C49) -> 38318 | H49: =DATEDIF(G49,"08-06-2023","y") -> 18 | I49: 0 | J49: 1137.47 | K49: tier - 3 | L49: tier - 2 | M49: R1013 | N49: =IF(ISBLANK(M49),"Unknown",M49) -> R1013
A50: Id2288 | B50: 2001 | C50: =ROUND(IF(ISBLANK(B50),AVERAGE($B$2:$B$2344),B50),0) -> 2001 | D50: Oct | E50: =IF(ISBLANK(D50),"Sep",D50) -> Oct | F50: 25 | G50: =DATEVALUE(F50&"-"&E50&"-"&C50) -> 37189 | H50: =DATEDIF(G50,"08-06-2023","y") -> 21 | I50: 0 | J50: 1141 | K50: tier - 3 | L50: tier - 1 | M50: R1013 | N50: =IF(ISBLANK(M50),"Unknown",M50) -> R1013
A51: Id2287 | B51: 2004 | C51: =ROUND(IF(ISBLANK(B51),AVERAGE($B$2:$B$2344),B51),0) -> 2004 | D51: Sep | E51: =IF(ISBLANK(D51),"Sep",D51) -> Sep | F51: 12 | G51: =DATEVALUE(F51&"-"&E51&"-"&C51) -> 38242 | H51: =DATEDIF(G51,"08-06-2023","y") -> 18 | I51: 0 | J51: 1141.45 | K51: tier - 3 | L51: tier - 3 | M51: R1013 | N51: =IF(ISBLANK(M51),"Unknown",M51) -> R1013
A52: Id2286 | B52: 2002 | C52: =ROUND(IF(ISBLANK(B52),AVERAGE($B$2:$B$2344),B52),0) -> 2002 | D52: Oct | E52: =IF(ISBLANK(D52),"Sep",D52) -> Oct | F52: 1 | G52: =DATEVALUE(F52&"-"&E52&"-"&C52) -> 37530 | H52: =DATEDIF(G52,"08-06-2023","y") -> 20 | I52: 0 | J52: 1142 | K52: tier - 3 | L52: tier - 2 | M52: R1011 | N52: =IF(ISBLANK(M52),"Unknown",M52) -> R1011
A53: Id2285 | B53: 2004 | C53: =ROUND(IF(ISBLANK(B53),AVERAGE($B$2:$B$2344),B53),0) -> 2004 | D53: Jun | E53: =IF(ISBLANK(D53),"Sep",D53) -> Jun | F53: 10 | G53: =DATEVALUE(F53&"-"&E53&"-"&C53) -> 38148 | H53: =DATEDIF(G53,"08-06-2023","y") -> 18 | I53: 0 | J53: 1146.8 | K53: tier - 2 | L53: tier - 2 | M53: R1013 | N53: =IF(ISBLANK(M53),"Unknown",M53) -> R1013
A54: Id2284 | B54: 2003 | C54: =ROUND(IF(ISBLANK(B54),AVERAGE($B$2:$B$2344),B54),0) -> 2003 | D54: Jun | E54: =IF(ISBLANK(D54),"Sep",D54) -> Jun | F54: 12 | G54: =DATEVALUE(F54&"-"&E54&"-"&C54) -> 37784 | H54: =DATEDIF(G54,"08-06-2023","y") -> 19 | I54: 0 | J54: 1149 | K54: tier - 2 | L54: tier - 1 | M54: R1012 | N54: =IF(ISBLANK(M54),"Unknown",M54) -> R1012
...

Sheet HealtCare
A1: Customer ID | B1: First Name | C1: BMI | D1: HBA1C | E1: Heart Issues | F1: Any Transplants | G1: Cancer history | H1: Number Of Major Surgeries | I1: smoker | J1: Weight Status | K1: Diabetice Status | L1: Date of Birth | M1: charges | N1: Hospital tier | O1: City tier | P1: State ID | Q1: Age
A2: Id1 | B2: =VLOOKUP($A2,'Customer Names'!A1:D2336,3,0) -> Kelly | C2: =VLOOKUP($A2,'Medical Examinations'!$A$1:$B$2336,2,FALSE) -> 47.41 | D2: =VLOOKUP($A2,'Medical Examinations'!A1:J2336,4,0) -> 7.47 | E2: =VLOOKUP(A2,'Medical Examinations'!A1:J2336,6,0) -> No | F2: =VLOOKUP($A2,'Medical Examinations'!$A$1:$J$2336,7,0) -> No | G2: =VLOOKUP(A2,'Medical Examinations'!A1:J2336,8,0) -> No | H2: =VLOOKUP(A2,'Medical Examinations'!A1:J2336,9,0) -> 0 | I2: =VLOOKUP(A2,'Medical Examinations'!A1:J2336,10,0) -> Yes | J2: =VLOOKUP($A2,'Medical Examinations'!A1:$J$2336,3,0) -> Obesity | K2: =VLOOKUP(A2,'Medical Examinations'!A1:J2336,5,0) -> Diabetes | L2: =VLOOKUP($A2,'Hospitalisation Details'!$A$1:$N$2344,7,0) -> 25123 | M2: =VLOOKUP($A2,'Hospitalisation Details'!$A$1:$N$2344,10,0) -> 63770.43 | N2: =VLOOKUP($A2,'Hospitalisation Details'!$A$1:$N$2344,11,0) -> tier - 1 | O2: =VLOOKUP($A2,'Hospitalisation Details'!$A$1:$N$2344,12,0) -> tier - 3 | P2: =VLOOKUP($A2,'Hospitalisation Details'!$A$1:$N$2344,14,0) -> R1013 | Q2: =VLOOKUP($A2,'Hospitalisation Details'!$A$1:$N$2344,8,0) -> 54
A3: Id2 | B3: =VLOOKUP($A3,'Customer Names'!A2:D2337,3,0) -> Matthew D | C3: =VLOOKUP($A3,'Medical Examinations'!$A$1:$B$2336,2,FALSE) -> 30.36 | D3: =VLOOKUP($A3,'Medical Examinations'!A2:J2337,4,0) -> 5.77 | E3: =VLOOKUP(A3,'Medical Examinations'!A2:J2337,6,0) -> No | F3: =VLOOKUP($A3,'Medical Examinations'!$A$1:$J$2336,7,0) -> No | G3: =VLOOKUP(A3,'Medical Examinations'!A2:J2337,8,0) -> No | H3: =VLOOKUP(A3,'Medical Examinations'!A2:J2337,9,0) -> 0 | I3: =VLOOKUP(A3,'Medical Examinations'!A2:J2337,10,0) -> Yes | J3: =VLOOKUP($A3,'Medical Examinations'!A2:$J$2336,3,0) -> Obesity | K3: =VLOOKUP(A3,'Medical Examinations'!A2:J2337,5,0) -> Prediabetes | L3: =VLOOKUP($A3,'Hospitalisation Details'!$A$1:$N$2344,7,0) -> 28284 | M3: =VLOOKUP($A3,'Hospitalisation Details'!$A$1:$N$2344,10,0) -> 62592.87 | N3: =VLOOKUP($A3,'Hospitalisation Details'!$A$1:$N$2344,11,0) -> tier - 2 | O3: =VLOOKUP($A3,'Hospitalisation Details'!$A$1:$N$2344,12,0) -> tier - 3 | P3: =VLOOKUP($A3,'Hospitalisation Details'!$A$1:$N$2344,14,0) -> R1013 | Q3: =VLOOKUP($A3,'Hospitalisation Details'!$A$1:$N$2344,8,0) -> 46
A4: Id3 | B4: =VLOOKUP($A4,'Customer Names'!A3:D2338,3,0) -> Phil | C4: =VLOOKUP($A4,'Medical Examinations'!$A$1:$B$2336,2,FALSE) -> 34.485 | D4: =VLOOKUP($A4,'Medical Examinations'!A3:J2338,4,0) -> 11.87 | E4: =VLOOKUP(A4,'Medical Examinations'!A3:J2338,6,0) -> Yes | F4: =VLOOKUP($A4,'Medical Examinations'!$A$1:$J$2336,7,0) -> No | G4: =VLOOKUP(A4,'Medical Examinations'!A3:J2338,8,0) -> No | H4: =VLOOKUP(A4,'Medical Examinations'!A3:J2338,9,0) -> 2 | I4: =VLOOKUP(A4,'Medical Examinations'!A3:J2338,10,0) -> Yes | J4: =VLOOKUP($A4,'Medical Examinations'!A3:$J$2336,3,0) -> Obesity | K4: =VLOOKUP(A4,'Medical Examinations'!A3:J2338,5,0) -> Diabetes | L4: =VLOOKUP($A4,'Hospitalisation Details'!$A$1:$N$2344,7,0) -> 25822 | M4: =VLOOKUP($A4,'Hospitalisation Details'!$A$1:$N$2344,10,0) -> 60021.4 | N4: =VLOOKUP($A4,'Hospitalisation Details'!$A$1:$N$2344,11,0) -> tier - 1 | O4: =VLOOKUP($A4,'Hospitalisation Details'!$A$1:$N$2344,12,0) -> tier - 1 | P4: =VLOOKUP($A4,'Hospitalisation Details'!$A$1:$N$2344,14,0) -> R1012 | Q4: =VLOOKUP($A4,'Hospitalisation Details'!$A$1:$N$2344,8,0) -> 52
A5: Id4 | B5: =VLOOKUP($A5,'Customer Names'!A4:D2339,3,0) -> Kelsey | C5: =VLOOKUP($A5,'Medical Examinations'!$A$1:$B$2336,2,FALSE) -> 38.095 | D5: =VLOOKUP($A5,'Medical Examinations'!A4:J2339,4,0) -> 6.05 | E5: =VLOOKUP(A5,'Medical Examinations'!A4:J2339,6,0) -> No | F5: =VLOOKUP($A5,'Medical Examinations'!$A$1:$J$2336,7,0) -> No | G5: =VLOOKUP(A5,'Medical Examinations'!A4:J2339,8,0) -> No | H5: =VLOOKUP(A5,'Medical Examinations'!A4:J2339,9,0) -> 0 | I5: =VLOOKUP(A5,'Medical Examinations'!A4:J2339,10,0) -> Yes | J5: =VLOOKUP($A5,'Medical Examinations'!A4:$J$2336,3,0) -> Obesity | K5: =VLOOKUP(A5,'Medical Examinations'!A4:J2339,5,0) -> Prediabetes | L5: =VLOOKUP($A5,'Hospitalisation Details'!$A$1:$N$2344,7,0) -> 33395 | M5: =VLOOKUP($A5,'Hospitalisation Details'!$A$1:$N$2344,10,0) -> 58571.07 | N5: =VLOOKUP($A5,'Hospitalisation Details'!$A$1:$N$2344,11,0) -> tier - 1 | O5: =VLOOKUP($A5,'Hospitalisation Details'!$A$1:$N$2344,12,0) -> tier - 3 | P5: =VLOOKUP($A5,'Hospitalisation Details'!$A$1:$N$2344,14,0) -> R1024 | Q5: =VLOOKUP($A5,'Hospitalisation Details'!$A$1:$N$2344,8,0) -> 32
A6: Id5 | B6: =VLOOKUP($A6,'Customer Names'!A5:D2340,3,0) -> Kristyn | C6: =VLOOKUP($A6,'Medical Examinations'!$A$1:$B$2336,2,FALSE) -> 35.53 | D6: =VLOOKUP($A6,'Medical Examinations'!A5:J2340,4,0) -> 5.45 | E6: =VLOOKUP(A6,'Medical Examinations'!A5:J2340,6,0) -> No | F6: =VLOOKUP($A6,'Medical Examinations'!$A$1:$J$2336,7,0) -> No | G6: =VLOOKUP(A6,'Medical Examinations'!A5:J2340,8,0) -> No | H6: =VLOOKUP(A6,'Medical Examinations'!A5:J2340,9,0) -> 0 | I6: =VLOOKUP(A6,'Medical Examinations'!A5:J2340,10,0) -> Yes | J6: =VLOOKUP($A6,'Medical Examinations'!A5:$J$2336,3,0) -> Obesity | K6: =VLOOKUP(A6,'Medical Examinations'!A5:J2340,5,0) -> Normal | L6: =VLOOKUP($A6,'Hospitalisation Details'!$A$1:$N$2344,7,0) -> 32678 | M6: =VLOOKUP($A6,'Hospitalisation Details'!$A$1:$N$2344,10,0) -> 55135.4 | N6: =VLOOKUP($A6,'Hospitalisation Details'!$A$1:$N$2344,11,0) -> tier - 1 | O6: =VLOOKUP($A6,'Hospitalisation Details'!$A$1:$N$2344,12,0) -> tier - 2 | P6: =VLOOKUP($A6,'Hospitalisation Details'!$A$1:$N$2344,14,0) -> R1012 | Q6: =VLOOKUP($A6,'Hospitalisation Details'!$A$1:$N$2344,8,0) -> 33
A7: Id6 | B7: =VLOOKUP($A7,'Customer Names'!A6:D2341,3,0) -> Russell B | C7: =VLOOKUP($A7,'Medical Examinations'!$A$1:$B$2336,2,FALSE) -> 32.8 | D7: =VLOOKUP($A7,'Medical Examinations'!A6:J2341,4,0) -> 6.59 | E7: =VLOOKUP(A7,'Medical Examinations'!A6:J2341,6,0) -> No | F7: =VLOOKUP($A7,'Medical Examinations'!$A$1:$J$2336,7,0) -> No | G7: =VLOOKUP(A7,'Medical Examinations'!A6:J2341,8,0) -> No | H7: =VLOOKUP(A7,'Medical Examinations'!A6:J2341,9,0) -> 0 | I7: =VLOOKUP(A7,'Medical Examinations'!A6:J2341,10,0) -> Yes | J7: =VLOOKUP($A7,'Medical Examinations'!A6:$J$2336,3,0) -> Obesity | K7: =VLOOKUP(A7,'Medical Examinations'!A6:J2341,5,0) -> Diabetes | L7: =VLOOKUP($A7,'Hospitalisation Details'!$A$1:$N$2344,7,0) -> 22862 | M7: =VLOOKUP($A7,'Hospitalisation Details'!$A$1:$N$2344,10,0) -> 52590.83 | N7: =VLOOKUP($A7,'Hospitalisation Details'!$A$1:$N$2344,11,0) -> tier - 1 | O7: =VLOOKUP($A7,'Hospitalisation Details'!$A$1:$N$2344,12,0) -> tier - 3 | P7: =VLOOKUP($A7,'Hospitalisation Details'!$A$1:$N$2344,14,0) -> R1011 | Q7: =VLOOKUP($A7,'Hospitalisation Details'!$A$1:$N$2344,8,0) -> 60
A8: Id7 | B8: =VLOOKUP($A8,'Customer Names'!A7:D2342,3,0) -> Scott | C8: =VLOOKUP($A8,'Medical Examinations'!$A$1:$B$2336,2,FALSE) -> 36.4 | D8: =VLOOKUP($A8,'Medical Examinations'!A7:J2342,4,0) -> 6.07 | E8: =VLOOKUP(A8,'Medical Examinations'!A7:J2342,6,0) -> No | F8: =VLOOKUP($A8,'Medical Examinations'!$A$1:$J$2336,7,0) -> No | G8: =VLOOKUP(A8,'Medical Examinations'!A7:J2342,8,0) -> No | H8: =VLOOKUP(A8,'Medical Examinations'!A7:J2342,9,0) -> 0 | I8: =VLOOKUP(A8,'Medical Examinations'!A7:J2342,10,0) -> Yes | J8: =VLOOKUP($A8,'Medical Examinations'!A7:$J$2336,3,0) -> Obesity | K8: =VLOOKUP(A8,'Medical Examinations'!A7:J2342,5,0) -> Prediabetes | L8: =VLOOKUP($A8,'Hospitalisation Details'!$A$1:$N$2344,7,0) -> 34634 | M8: =VLOOKUP($A8,'Hospitalisation Details'!$A$1:$N$2344,10,0) -> 51194.56 | N8: =VLOOKUP($A8,'Hospitalisation Details'!$A$1:$N$2344,11,0) -> tier - 1 | O8: =VLOOKUP($A8,'Hospitalisation Details'!$A$1:$N$2344,12,0) -> tier - 3 | P8: =VLOOKUP($A8,'Hospitalisation Details'!$A$1:$N$2344,14,0) -> R1011 | Q8: =VLOOKUP($A8,'Hospitalisation Details'!$A$1:$N$2344,8,0) -> 28
A9: Id8 | B9: =VLOOKUP($A9,'Customer Names'!A8:D2343,3,0) -> Stephen | C9: =VLOOKUP($A9,'Medical Examinations'!$A$1:$B$2336,2,FALSE) -> 36.96 | D9: =VLOOKUP($A9,'Medical Examinations'!A8:J2343,4,0) -> 7.93 | E9: =VLOOKUP(A9,'Medical Examinations'!A8:J2343,6,0) -> No | F9: =VLOOKUP($A9,'Medical Examinations'!$A$1:$J$2336,7,0) -> No | G9: =VLOOKUP(A9,'Medical Examinations'!A8:J2343,8,0) -> No | H9: =VLOOKUP(A9,'Medical Examinations'!A8:J2343,9,0) -> 3 | I9: =VLOOKUP(A9,'Medical Examinations'!A8:J2343,10,0) -> Yes | J9: =VLOOKUP($A9,'Medical Examinations'!A8:$J$2336,3,0) -> Obesity | K9: =VLOOKUP(A9,'Medical Examinations'!A8:J2343,5,0) -> Diabetes | L9: =VLOOKUP($A9,'Hospitalisation Details'!$A$1:$N$2344,7,0) -> 21363 | M9: =VLOOKUP($A9,'Hospitalisation Details'!$A$1:$N$2344,10,0) -> 49577.66 | N9: =VLOOKUP($A9,'Hospitalisation Details'!$A$1:$N$2344,11,0) -> tier - 2 | O9: =VLOOKUP($A9,'Hospitalisation Details'!$A$1:$N$2344,12,0) -> tier - 2 | P9: =VLOOKUP($A9,'Hospitalisation Details'!$A$1:$N$2344,14,0) -> R1013 | Q9: =VLOOKUP($A9,'Hospitalisation Details'!$A$1:$N$2344,8,0) -> 64
A10: Id9 | B10: =VLOOKUP($A10,'Customer Names'!A9:D2344,3,0) -> Patrick R | C10: =VLOOKUP($A10,'Medical Examinations'!$A$1:$B$2336,2,FALSE) -> 41.14 | D10: =VLOOKUP($A10,'Medical Examinations'!A9:J2344,4,0) -> 9.58 | E10: =VLOOKUP(A10,'Medical Examinations'!A9:J2344,6,0) -> Yes | F10: =VLOOKUP($A10,'Medical Examinations'!$A$1:$J$2336,7,0) -> No | G10: =VLOOKUP(A10,'Medical Examinations'!A9:J2344,8,0) -> Yes | H10: =VLOOKUP(A10,'Medical Examinations'!A9:J2344,9,0) -> 1 | I10: =VLOOKUP(A10,'Medical Examinations'!A9:J2344,10,0) -> Yes | J10: =VLOOKUP($A10,'Medical Examinations'!A9:$J$2336,3,0) -> Obesity | K10: =VLOOKUP(A10,'Medical Examinations'!A9:J2344,5,0) -> Diabetes | L10: =VLOOKUP($A10,'Hospitalisation Details'!$A$1:$N$2344,7,0) -> 23258 | M10: =VLOOKUP($A10,'Hospitalisation Details'!$A$1:$N$2344,10,0) -> 48970.25 | N10: =VLOOKUP($A10,'Hospitalisation Details'!$A$1:$N$2344,11,0) -> tier - 1 | O10: =VLOOKUP($A10,'Hospitalisation Details'!$A$1:$N$2344,12,0) -> tier - 2 | P10: =VLOOKUP($A10,'Hospitalisation Details'!$A$1:$N$2344,14,0) -> R1013 | Q10: =VLOOKUP($A10,'Hospitalisation Details'!$A$1:$N$2344,8,0) -> 59
A11: Id10 | B11: =VLOOKUP($A11,'Customer Names'!A10:D2345,3,0) -> Brooke N | C11: =VLOOKUP($A11,'Medical Examinations'!$A$1:$B$2336,2,FALSE) -> 38.06 | D11: =VLOOKUP($A11,'Medical Examinations'!A10:J2345,4,0) -> 10.79 | E11: =VLOOKUP(A11,'Medical Examinations'!A10:J2345,6,0) -> No | F11: =VLOOKUP($A11,'Medical Examinations'!$A$1:$J$2336,7,0) -> No | G11: =VLOOKUP(A11,'Medical Examinations'!A10:J2345,8,0) -> No | H11: =VLOOKUP(A11,'Medical Examinations'!A10:J2345,9,0) -> 0 | I11: =VLOOKUP(A11,'Medical Examinations'!A10:J2345,10,0) -> Yes | J11: =VLOOKUP($A11,'Medical Examinations'!A10:$J$2336,3,0) -> Obesity | K11: =VLOOKUP(A11,'Medical Examinations'!A10:J2345,5,0) -> Diabetes | L11: =VLOOKUP($A11,'Hospitalisation Details'!$A$1:$N$2344,7,0) -> 28853 | M11: =VLOOKUP($A11,'Hospitalisation Details'!$A$1:$N$2344,10,0) -> 48885.14 | N11: =VLOOKUP($A11,'Hospitalisation Details'!$A$1:$N$2344,11,0) -> tier - 1 | O11: =VLOOKUP($A11,'Hospitalisation Details'!$A$1:$N$2344,12,0) -> tier - 2 | P11: =VLOOKUP($A11,'Hospitalisation Details'!$A$1:$N$2344,14,0) -> R1013 | Q11: =VLOOKUP($A11,'Hospitalisation Details'!$A$1:$N$2344,8,0) -> 44
A12: Id11 | B12: =VLOOKUP($A12,'Customer Names'!A11:D2346,3,0) -> Paola Andrea | C12: =VLOOKUP($A12,'Medical Examinations'!$A$1:$B$2336,2,FALSE) -> 37.7 | D12: =VLOOKUP($A12,'Medical Examinations'!A11:J2346,4,0) -> 5.96 | E12: =VLOOKUP(A12,'Medical Examinations'!A11:J2346,6,0) -> Yes | F12: =VLOOKUP($A12,'Medical Examinations'!$A$1:$J$2336,7,0) -> No | G12: =VLOOKUP(A12,'Medical Examinations'!A11:J2346,8,0) -> No | H12: =VLOOKUP(A12,'Medical Examinations'!A11:J2346,9,0) -> 2 | I12: =VLOOKUP(A12,'Medical Examinations'!A11:J2346,10,0) -> Yes | J12: =VLOOKUP($A12,'Medical Examinations'!A11:$J$2336,3,0) -> Obesity | K12: =VLOOKUP(A12,'Medical Examinations'!A11:J2346,5,0) -> Prediabetes | L12: =VLOOKUP($A12,'Hospitalisation Details'!$A$1:$N$2344,7,0) -> 21753 | M12: =VLOOKUP($A12,'Hospitalisation Details'!$A$1:$N$2344,10,0) -> 48824.45 | N12: =VLOOKUP($A12,'Hospitalisation Details'!$A$1:$N$2344,11,0) -> tier - 2 | O12: =VLOOKUP($A12,'Hospitalisation Details'!$A$1:$N$2344,12,0) -> tier - 1 | P12: =VLOOKUP($A12,'Hospitalisation Details'!$A$1:$N$2344,14,0) -> R1011 | Q12: =VLOOKUP($A12,'Hospitalisation Details'!$A$1:$N$2344,8,0) -> 63
A13: Id12 | B13: =VLOOKUP($A13,'Customer Names'!A12:D2347,3,0) -> David | C13: =VLOOKUP($A13,'Medical Examinations'!$A$1:$B$2336,2,FALSE) -> 42.13 | D13: =VLOOKUP($A13,'Medical Examinations'!A12:J2347,4,0) -> 11.9 | E13: =VLOOKUP(A13,'Medical Examinations'!A12:J2347,6,0) -> No | F13: =VLOOKUP($A13,'Medical Examinations'!$A$1:$J$2336,7,0) -> No | G13: =VLOOKUP(A13,'Medical Examinations'!A12:J2347,8,0) -> No | H13: =VLOOKUP(A13,'Medical Examinations'!A12:J2347,9,0) -> 0 | I13: =VLOOKUP(A13,'Medical Examinations'!A12:J2347,10,0) -> Yes | J13: =VLOOKUP($A13,'Medical Examinations'!A12:$J$2336,3,0) -> Obesity | K13: =VLOOKUP(A13,'Medical Examinations'!A12:J2347,5,0) -> Diabetes | L13: =VLOOKUP($A13,'Hospitalisation Details'!$A$1:$N$2344,7,0) -> 24042 | M13: =VLOOKUP($A13,'Hospitalisation Details'!$A$1:$N$2344,10,0) -> 48675.52 | N13: =VLOOKUP($A13,'Hospitalisation Details'!$A$1:$N$2344,11,0) -> tier - 1 | O13: =VLOOKUP($A13,'Hospitalisation Details'!$A$1:$N$2344,12,0) -> tier - 2 | P13: =VLOOKUP($A13,'Hospitalisation Details'!$A$1:$N$2344,14,0) -> R1013 | Q13: =VLOOKUP($A13,'Hospitalisation Details'!$A$1:$N$2344,8,0) -> 57
... A2336: Id2335 | B2336: =VLOOKUP($A2336,'Customer Names'!A2335:D4670,3,0) -> Aaron K | C2336: =VLOOKUP($A2336,'Medical Examinations'!$A$1:$B$2336,2,FALSE) -> 17.58 | D2336: =VLOOKUP($A2336,'Medical Examinations'!A2335:J4670,4,0) -> 4.51 | E2336: =VLOOKUP(A2336,'Medical Examinations'!A2335:J4670,6,0) -> No | F2336: =VLOOKUP($A2336,'Medical Examinations'!$A$1:$J$2336,7,0) -> No | G2336: =VLOOKUP(A2336,'Medical Examinations'!A2335:J4670,8,0) -> No | H2336: =VLOOKUP(A2336,'Medical Examinations'!A2335:J4670,9,0) -> 1 | I2336: =VLOOKUP(A2336,'Medical Examinations'!A2335:J4670,10,0) -> No | J2336: =VLOOKUP($A2336,'Medical Examinations'!A2335:$J$2336,3,0) -> Underweight | K2336: =VLOOKUP(A2336,'Medical Examinations'!A2335:J4670,5,0) -> Normal | L2336: =VLOOKUP($A2336,'Hospitalisation Details'!$A$1:$N$2344,7,0) -> 33794 | M2336: =VLOOKUP($A2336,'Hospitalisation Details'!$A$1:$N$2344,10,0) -> 563.84 | N2336: =VLOOKUP($A2336,'Hospitalisation Details'!$A$1:$N$2344,11,0) -> tier - 2 | O2336: =VLOOKUP($A2336,'Hospitalisation Details'!$A$1:$N$2344,12,0) -> tier - 3 | P2336: =VLOOKUP($A2336,'Hospitalisation Details'!$A$1:$N$2344,14,0) -> R1013 | Q2336: =VLOOKUP($A2336,'Hospitalisation Details'!$A$1:$N$2344,8,0) -> 30

Sheet Pie Chart
B4: Row Labels | C4: Count of Cancer history | G4: Row Labels | H4: Sum of Number Of Major Surgeries | I4: Average of HBA1C
B5: No | C5: 1847 | G5: No | H5: 1417 | I5: 6.6704427
B6: Yes | C6: 488 | G6: yes | H6: 162 | I6: 5.1876389
B7: Grand Total | C7: 2335 | G7: Grand Total | H7: 1579 | I7: 6.5789979

Sheet Bar Chart
B2: Average of charges | C2: Column Labels
B3: Row Labels | C3: Diabetes | D3: Normal | E3: Prediabetes | F3: Grand Total
B4: Normal Weight | C4: 12464.137 | D4: 7897.0779 | E4: 10492.131 | F4: 9842.5103
B5: Obesity | C5: 19347.657 | D5: 15188.437 | E5: 15353.902 | F5: 16661.463
B6: Overweight | C6: 14231.866 | D6: 10323.941 | E6: 9737.9402 | F6: 11424.674
B7: Underweight | C7: 7442.9649 | D7: 6911.0056 | E7: 5647.7483 | F7: 6899.3175
B8: Grand Total | C8: 16120.287 | D8: 12090.723 | E8: 12532.263 | F8: 13529.918
B14: Average of charges | C14: Column Labels
B15: Row Labels | C15: tier - 1 | D15: tier - 2 | E15: tier - 3 | F15: tire - 2 | G15: Grand Total
B16: R1011 | C16: 33081.374 | D16: 18997.281 | E16: 9250.3618 | G16: 19466.246
B17: R1012 | C17: 26111.458 | D17: 10334.279 | E17: 10179.942 | G17: 12016.474
B18: R1013 | C18: 31328.102 | D18: 8459.9777 | E18: 6890.7568 | F18: 700 | G18: 10514.94
B19: R1014 | C19: 13891.86 | D19: 2395.17 | E19: 16950.485 | G19: 13478.057
B20: R1015 | C20: 21523.52 | D20: 15675.543 | E20: 7570.755 | G20: 13948.61
B21: R1016 | C21: 39868.616 | D21: 16075.963 | E21: 8133.0084 | G21: 13589.263
B22: R1017 | C22: 34070.596 | D22: 11365.622 | E22: 8667.3662 | G22: 14806.108
B23: R1018 | C23: 33475.82 | D23: 10139.553 | E23: 12570.97 | G23: 13272.787
B24: R1019 | C24: 27621.61 | D24: 8116.72 | E24: 12706.976 | G24: 13633.143
B25: R1020 | D25: 6760.5433 | E25: 11716.453 | G25: 9238.4983
B26: R1021 | D26: 7668.1787 | E26: 11518.786 | G26: 8933.3781
B27: R1022 | D27: 10102.027 | E27: 11637.812 | G27: 10650.521
B28: R1023 | C28: 18261.757 | D28: 13457.095 | E28: 12785.637 | G28: 13786.149
B29: R1024 | C29: 32732.187 | D29: 10174.346 | E29: 13360.979 | G29: 12865.149
B30: R1025 | D30: 6886.0368 | E30: 10510.314 | G30: 8788.7823
B31: R1026 | C31: 18709.798 | D31: 11919.608 | E31: 12296.78 | G31: 12489.921
B32: Unknown | C32: 20996.53 | G32: 20996.53
B33: Grand Total | C33: 30129.199 | D33: 11873.62 | E33: 9462.2693 | F33: 700 | G33: 13529.918

Sheet Line Chart
C4: Row Labels | D4: Average of BMI | E4: Average of HBA1C | L4: Row Labels | M4: Average of charges
C5: 18-27 | D5: 30.220757 | E5: 5.5714974 | L5: 18-27 | M5: 8622.6848
C6: 28-37 | D6: 31.278782 | E6: 5.540978 | L6: 28-37 | M6: 12159.759
C7: 38-47 | D7: 30.721397 | E7: 6.5336235 | L7: 38-47 | M7: 14848.525
C8: 48-57 | D8: 31.264466 | E8: 8.049084 | L8: 48-57 | M8: 16480.545
C9: 58-67 | D9: 32.056404 | E9: 8.1002553 | L9: 58-67 | M9: 19232.183
C10: Grand Total | D10: 30.972649 | E10: 6.5789979 | L10: Grand Total | M10: 13529.918

Sheet Dashboard
